Workbook

Sheet 1.1Defunciones por Edades China
B8: 80+ | C8: 0.148
B9: 70 - 79 | C9: 0.08
B10: 60 - 69 | C10: 0.036
B11: 50 - 59 | C11: 0.013
B12: 40 - 49 | C12: 0.004
B13: 30 - 39 | C13: 0.002
B14: 20 - 29 | C14: 0.002
B15: 10 - 19 | C15: 0.002

Sheet 1.3 Defunciones por Estado
A1: cve_ent | B1: poblacion | C1: nombre | D1: 43907 | E1: 43908 | F1: 43909 | G1: 43910 | H1: 43911 | I1: 43912 | J1: 43913 | K1: 43914 | L1: 43915 | M1: 43916 | N1: 43917 | O1: 43918 | P1: 43919 | Q1: 43920 | R1: 43921 | S1: 43922 | T1: 43923 | U1: 43924 | V1: 43925 | W1: 43926 | X1: 43927 | Y1: 43928 | Z1: 43929 | AA1: 43930 | AB1: 43931 | AC1: 43932 | AD1: 43933 | AE1: 43934 | AF1: 43935 | AG1: 43936 | AH1: 43937 | AI1: 43938 | AJ1: 43939 | AK1: 43940 | AL1: 43941 | AM1: 43942 | AN1: 43943 | AO1: 43944 | AP1: 43945 | AQ1: 43946 | AR1: 43947 | AS1: 43948 | AT1: 43949 | AU1: 43950 | AV1: 43951 | AW1: 43952 | AX1: 43953 | AY1: 43954 | AZ1: 43955 | BA1: 43956 | BB1: 43957 | BC1: 43958 | BD1: 43959 | BE1: 43960 | BF1: 43961 | BG1: 43962 | BH1: 43963 | BI1: 43964 | BJ1: 43965 | BK1: 43966 | BL1: 43967 | BM1: 43968 | BN1: 43969 | BO1: 43970 | BP1: 43971 | BQ1: 43972 | BR1: 43973 | BS1: 43974 | BT1: 43975 | BU1: 43976 | BV1: 43977 | BW1: 43978 | BX1: 43979 | BY1: 43980 | BZ1: 43981 | CA1: 43982 | CB1: 43983 | CC1: 43984 | CD1: 43985 | CE1: 43986 | CF1: 43987 | CG1: 43988 | CH1: 43989 | CI1: 43990 | CJ1: 43991 | CK1: 43992 | CL1: 43993 | CM1: 43994 | CN1: 43995 | CO1: 43996 | CP1: 43997 | CQ1: 43998 | CR1: 43999 | CS1: 44000 | CT1: 44001 | CU1: 44002 | CV1: 44003 | CW1: 44004 | CX1: 44005 | CY1: 44006 | CZ1: 44007 | DA1: 44008 | DB1: 44009 | DC1: 44010 | DD1: 44011 | DE1: 44012 | DF1: 44013 | DG1: 44014 | DH1: 44015 | DI1: 44016 | DJ1: 44017 | DK1: 44018 | DL1: 44019 | DM1: 44020 | DN1: 44021 | DO1: 44022 | DP1: 44023 | DQ1: 44024 | DR1: 44025 | DS1: 44026 | DT1: 44027 | DU1: 44028 | DV1: 44029 | DW1: 44030 | DX1: 44031 | DY1: 44032 | DZ1: 44033 | EA1: 44034 | EB1: 44035 | EC1: 44036 | ED1: 44037 | EE1: 44038 | EF1: 44039 | EG1: 44040 | EH1: 44041 | EI1: 44042 | EJ1: 44043 | EK1: 44044 | EL1: 44045 | EM1: 44046 | EN1: 44047 | EO1: 44048 | EP1: 44049 | EQ1: 44050 | ER1: 44051 | ES1: 44052 | ET1: 44053 | EU1: 44054 | EV1: 44055 | EW1: 44056 | EX1: 44057 | EY1: 44058 | EZ1: 44059 | FA1: 44060 | FB1: 44061 | FC1: 44062 | FD1: 44063 | FE1: 44064 | FF1: 44065 | FG1: 44066 | FH1: 44067 | FI1: 44068 | FJ1: 44069 | FK1: 44070 | FL1: 44071 | FM1: 44072 | FN1: 44073 | FO1: 44074 | FP1: 44075 | FQ1: 44076 | FR1: 44077 | FS1: 44078 | FT1: 44079 | FU1: 44080 | FV1: 44081 | FW1: 44082 | FX1: 44083 | FY1: 44084 | FZ1: 44085 | GA1: 44086 | GB1: 44087 | GC1: 44088 | GD1: 44089 | GE1: 44090 | GF1: 44091 | GG1: 44092 | GH1: 44093 | GI1: 44094 | GJ1: 44095 | GK1: 44096 | GL1: 44097 | GM1: 44098 | GN1: 44099 | GO1: 44100 | GP1: 44101 | GQ1: 44102 | GR1: 44103 | GS1: 44104 | GT1: 44105 | GU1: 44106 | GV1: 44107 | GW1: 44108 | GX1: 44109 | GY1: 44110 | GZ1: 44111 | HA1: 44112 | HB1: 44113 | HC1: 44114 | HD1: 44115 | HE1: 44116 | HF1: 44117 | HG1: 44118 | HH1: 44119 | HI1: 44120 | HJ1: 44121 | HK1: 44122 | HL1: 44123 | HM1: 44124 | HN1: 44125 | HO1: 44126 | HP1: 44127 | HQ1: 44128 | HR1: 44129 | HS1: 44130 | HT1: 44131 | HU1: 44132 | HV1: 44133 | HW1: 44134 | HX1: 44135 | HY1: 44136 | HZ1: 44137 | IA1: 44138 | IB1: 44139 | IC1: 44140 | ID1: 44141 | IE1: 44142 | IF1: 44143 | IG1: 44144 | IH1: 44145 | II1: 44146 | IJ1: 44147 | IK1: 44148 | IL1: 44149 | IM1: 44150 | IN1: 44151 | IO1: 44152 | IP1: 44153 | IQ1: 44154 | IR1: 44155 | IS1: 44156 | IT1: 44157 | IU1: 44158 | IV1: 44159 | IW1: 44160 | IX1: 44161 | IY1: 44162 | IZ1: 44163 | JA1: 44164 | JB1: 44165 | JC1: 44166 | JD1: 44167 | JE1: 44168 | JF1: 44169 | JG1: 44170 | JH1: 44171 | JI1: 44172 | JJ1: 44173 | JK1: 44174 | JL1: 44175 | JM1: 44176 | JN1: 44177 | JO1: 44178 | JP1: 44179 | JQ1: 44180 | JR1: 44181 | JS1: 44182 | JT1: 44183 | JU1: 44184 | JV1: 44185 | JW1: 44186 | JX1: 44187 | JY1: 44188 | JZ1: 44189 | KA1: 44190 | KB1: 44191 | KC1: 44192 | KD1: 44193 | KE1: 44194 | KF1: 44195 | KG1: 44196 | KH1: 44197 | KI1: 44198 | KJ1: 44199 | KK1: 44200 | KL1: 44201 | KM1: 44202 | KN1: 44203 | KO1: 44204 | KP1: 44205 | KQ1: 44206 | KR1: 44207 | KS1: 44208 | KT1: 44209 | KU1: 44210 | KV1: 44211 | KW1: 44212 | KX1: 44213 | KY1: 44214 | KZ1: 44215 | LA1: 44216 | LB1: 44217 | LC1: 44218 | LD1: 44219 | LE1: 44220 | LF1: 44221 | LG1: 44222 | LH1: 44223 | LI1: 44224 | LJ1: 44225 | LK1: 44226 | LL1: 44227 | LM1: 44228 | LN1: 44229 | LO1: 44230 | LP1: 44231 | LQ1: 44232 | LR1: 44233 | LS1: 44234 | LT1: 44235 | LU1: 44236 | LV1: 44237 | LW1: 44238 | LX1: 44239 | LY1: 44240 | LZ1: 44241 | MA1: 44242 | MB1: 44243 | MC1: 44244 | MD1: 44245 | ME1: 44246 | MF1: 44247 | MG1: 44248 | MH1: 44249 | MI1: 44250 | MJ1: 44251 | MK1: 44252 | ML1: 44253 | MM1: 44254 | MN1: 44255 | MO1: 44256 | MP1: 44257 | MQ1: 44258 | MR1: 44259 | MS1: 44260 | MT1: 44261 | MU1: 44262 | MV1: 44263 | MW1: 44264 | MX1: 44265 | MY1: 44266 | MZ1: 44267 | NA1: 44268 | NB1: 44269 | NC1: 44270 | ND1: 44271 | NE1: 44272 | NF1: 44273 | NG1: 44274 | NH1: 44275 | NI1: 44276 | NJ1: 44277 | NK1: 44278 | NL1: 44279 | NM1: 44280 | NN1: 44281 | NO1: 44282 | NP1: 44283 | NQ1: 44284 | NR1: 44285 | NS1: 44286 | NT1: 44287 | NU1: 44288 | NV1: 44289 | NW1: 44290 | NX1: 44291 | NY1: 44292 | NZ1: 44293 | OA1: 44294 | OB1: 44295 | OC1: 44296 | OD1: 44297 | OE1: 44298 | OF1: 44299 | OG1: 44300 | OH1: 44301 | OI1: 44302 | OJ1: 44303 | OK1: 44304 | OL1: 44305 | OM1: 44306 | ON1: 44307 | OO1: 44308 | OP1: 44309 | OQ1: 44310 | OR1: 44311 | OS1: 44312 | OT1: 44313 | OU1: 44314 | OV1: 44315 | OW1: 44316 | OX1: 44317 | OY1: 44318 | OZ1: 44319 | PA1: 44320 | PB1: 44321 | PC1: 44322 | PD1: 44323 | PE1: 44324 | PF1: 44325 | PG1: 44326 | PH1: 44327 | PI1: 44328 | PJ1: 44329 | PK1: 44330 | PL1: 44331 | PM1: 44332 | PN1: 44333 | PO1: 44334 | PP1: 44335 | PQ1: 44336 | PR1: 44337 | PS1: 44338 | PT1: 44339 | PU1: 44340 | PV1: 44341 | PW1: 44342 | PX1: 44343 | PY1: 44344 | PZ1: 44345 | QA1: 44346 | QB1: 44347 | QC1: 44348 | QD1: 44349 | QE1: 44350 | QF1: 44351 | QG1: 44352 | QH1: 44353 | QI1: 44354 | QJ1: 44355 | QK1: 44356 | QL1: 44357 | QM1: 44358 | QN1: 44359 | QO1: 44360 | QP1: 44361 | QQ1: 44362 | QR1: 44363 | QS1: 44364 | QT1: 44365 | QU1: 44366 | QV1: 44367 | QW1: 44368 | QX1: 44369 | QY1: 44370 | QZ1: 44371 | RA1: 44372 | RB1: 44373 | RC1: 44374 | RD1: 44375 | RE1: 44376 | RF1: 44377 | RG1: 44378 | RH1: 44379 | RI1: 44380 | RJ1: 44381 | RK1: 44382 | RL1: 44383 | RM1: 44384 | RN1: 44385 | RO1: 44386 | RP1: 44387 | RQ1: 44388 | RR1: 44389 | RS1: 44390 | RT1: 44391 | RU1: 44392 | RV1: 44393 | RW1: 44394 | RX1: 44395 | RY1: 44396 | RZ1: 44397 | SA1: 44398 | SB1: 44399 | SC1: 44400 | SD1: 44401 | SE1: 44402 | SF1: 44403 | SG1: 44404 | SH1: 44405 | SI1: 44406 | SJ1: 44407 | SK1: 44408 | SL1: 44409 | SM1: 44410 | SN1: 44411 | SO1: 44412 | SP1: 44413 | SQ1: 44414 | SR1: 44415 | SS1: 44416 | ST1: 44417 | SU1: 44418 | SV1: 44419 | SW1: 44420 | SX1: 44421 | SY1: 44422 | SZ1: 44423 | TA1: 44424 | TB1: 44425 | TC1: 44426 | TD1: 44427 | TE1: 44428 | TF1: 44429 | TG1: 44430 | TH1: 44431 | TI1: 44432 | TJ1: 44433 | TK1: 44434 | TL1: 44435 | TM1: 44436 | TN1: 44437 | TO1: 44438 | TP1: 44439 | TQ1: 44440 | TR1: 44441 | TS1: 44442 | TT1: 44443 | TU1: 44444 | TV1: 44445 | TW1: 44446 | TX1: 44447 | TY1: 44448 | TZ1: 44449 | UA1: 44450 | UB1: 44451 | UC1: 44452 | UD1: 44453 | UE1: 44454 | UF1: 44455 | UG1: 44456 | UH1: 44457 | UI1: 44458 | UJ1: 44459 | UK1: 44460 | UL1: 44461 | UM1: 44462 | UN1: 44463 | UO1: 44464 | UP1: 44465 | UQ1: 44466 | UR1: 44467 | US1: 44468 | UT1: 44469 | UU1: 44470 | UV1: 44471 | UW1: 44472 | UX1: 44473 | UY1: 44474 | UZ1: 44475 | VA1: 44476 | VB1: 44477 | VC1: 44478 | VD1: 44479 | VE1: 44480 | VF1: 44481 | VG1: 44482 | VH1: 44483 | VI1: 44484 | VJ1: 44485 | VK1: 44486 | VL1: 44487 | VM1: 44488 | VN1: 44489 | VO1: 44490 | VP1: 44491 | VQ1: 44492 | VR1: 44493 | VS1: 44494 | VT1: 44495 | VU1: 44496 | VV1: 44497 | VW1: 44498 | VX1: 44499 | VY1: 44500 | VZ1: 44501 | WA1: 44502 | WB1: 44503 | WC1: 44504 | WD1: 44505 | WE1: 44506 | WF1: 44507 | WG1: 44508 | WH1: 44509 | WI1: 44510 | WJ1: 44511 | WK1: 44512 | WL1: 44513 | WM1: 44514 | WN1: 44515 | WO1: 44516 | WP1: 44517 | WQ1: 44518 | WR1: 44519 | WS1: 44520 | WT1: 44521 | WU1: 44522 | WV1: 44523 | WW1: 44524 | WX1: 44525 | WY1: 44526 | WZ1: 44527 | XA1: 44528 | XB1: 44529 | XC1: 44530 | XD1: 44531 | XE1: 44532 | XF1: 44533 | XG1: 44534 | XH1: 44535 | XI1: 44536 | XJ1: 44537 | XK1: 44538 | XL1: 44539 | XM1: 44540 | XN1: 44541 | XO1: 44542 | XP1: 44543 | XQ1: 44544 | XR1: 44545 | XS1: 44546 | XT1: 44547 | XU1: 44548 | XV1: 44549 | XW1: 44550 | XX1: 44551 | XY1: 44552 | XZ1: 44553 | YA1: 44554 | YB1: 44555 | YC1: 44556 | YD1: 44557 | YE1: 44558 | YF1: 44559 | YG1: 44560 | YH1: 44561 | YI1: 44562 | YJ1: 44563 | YK1: 44564 | YL1: 44565 | YM1: 44566 | YN1: 44567 | YO1: 44568 | YP1: 44569 | YQ1: 44570 | YR1: 44571 | YS1: 44572 | YT1: 44573 | YU1: 44574 | YV1: 44575 | YW1: 44576 | YX1: 44577 | YY1: 44578 | YZ1: 44579 | ZA1: 44580 | ZB1: 44581 | ZC1: 44582 | ZD1: 44583 | ZE1: 44584 | ZF1: 44585 | ZG1: 44586 | ZH1: 44587 | ZI1: 44588 | ZJ1: 44589 | ZK1: 44590 | ZL1: 44591 | ZM1: 44592 | ZN1: 44593 | ZO1: 44594 | ZP1: 44595 | ZQ1: 44596 | ZR1: 44597 | ZS1: 44598 | ZT1: 44599 | ZU1: 44600 | ZV1: 44601 | ZW1: 44602 | ZX1: 44603 | ZY1: 44604 | ZZ1: 44605 | AAA1: 44606 | AAB1: 44607 | AAC1: 44608 | AAD1: 44609 | AAE1: 44610 | AAF1: 44611 | AAG1: 44612 | AAH1: 44613 | AAI1: 44614 | AAJ1: 44615 | AAK1: 44616 | AAL1: 44617 | AAM1: 44618 | AAN1: 44619 | AAO1: 44620 | AAP1: 44621 | AAQ1: 44622 | AAR1: 44623 | AAS1: 44624 | AAT1: 44625 | AAU1: 44626 | AAV1: 44627 | AAW1: 44628 | AAX1: 44629 | AAY1: 44630 | AAZ1: 44631 | ABA1: 44632 | ABB1: 44633 | ABC1: 44634 | ABD1: 44635 | ABE1: 44636 | ABF1: 44637 | ABG1: 44638 | ABH1: 44639 | ABI1: 44640 | ABJ1: 44641 | ABK1: 44642 | ABL1: 44643 | ABM1: 44644 | ABN1: 44645 | ABO1: 44646 | ABP1: 44647 | ABQ1: 44648 | ABR1: 44649 | ABS1: 44650 | ABT1: 44651 | ABU1: 44652 | ABV1: 44653 | ABW1: 44654 | ABX1: 44655 | ABY1: 44656 | ABZ1: 44657 | ACA1: 44658 | ACB1: 44659 | ACC1: 44660 | ACD1: 44661 | ACE1: 44662 | ACF1: 44663 | ACG1: 44664 | ACH1: 44665 | ACI1: 44666 | ACJ1: 44667 | ACK1: 44668 | ACL1: 44669 | ACM1: 44670 | ACN1: 44671 | ACO1: 44672 | ACP1: 44673 | ACQ1: 44674 | ACR1: 44675 | ACS1: 44676 | ACT1: 44677 | ACU1: 44678 | ACV1: 44679 | ACW1: 44680 | ACX1: 44681 | ACY1: 44682 | ACZ1: 44683 | ADA1: 44684 | ADB1: 44685 | ADC1: 44686 | ADD1: 44687 | ADE1: 44688 | ADF1: 44689 | ADG1: 44690 | ADH1: 44691 | ADI1: 44692 | ADJ1: 44693 | ADK1: 44694 | ADL1: 44695 | ADM1: 44696 | ADN1: 44697 | ADO1: 44698 | ADP1: 44699 | ADQ1: 44700 | ADR1: 44701 | ADS1: 44702 | ADT1: 44703 | ADU1: 44704 | ADV1: 44705 | ADW1: 44706 | ADX1: 44707 | ADY1: 44708 | ADZ1: 44709 | AEA1: 44710 | AEB1: 44711 | AEC1: 44712 | AED1: 44713 | AEE1: 44714 | AEF1: 44715 | AEG1: 44716 | AEH1: 44717 | AEI1: 44718 | AEJ1: 44719 | AEK1: 44720 | AEL1: 44721 | AEM1: 44722 | AEN1: 44723 | AEO1: 44724 | AEP1: 44725 | AEQ1: 44726 | AER1: 44727 | AES1: 44728 | AET1: 44729 | AEU1: 44730 | AEV1: 44731 | AEW1: 44732 | AEX1: 44733 | AEY1: 44734 | AEZ1: 44735 | AFA1: 44736 | AFB1: 44737 | AFC1: 44738 | AFD1: 44739 | AFE1: 44740 | AFF1: 44741 | AFG1: 44742 | AFH1: 44743 | AFI1: 44744 | AFJ1: 44745 | AFK1: 44746 | AFL1: 44747 | AFM1: 44748 | AFN1: 44749 | AFO1: 44750 | AFP1: 44751 | AFQ1: 44752 | AFR1: 44753 | AFS1: 44754 | AFT1: 44755 | AFU1: 44756 | AFV1: 44757 | AFW1: 44758 | AFX1: 44759 | AFY1: 44760 | AFZ1: 44761 | AGA1: 44762 | AGB1: 44763 | AGC1: 44764 | AGD1: 44765 | AGE1: 44766 | AGF1: 44767 | AGG1: 44768 | AGH1: 44769 | AGI1: 44770 | AGJ1: 44771 | AGK1: 44772 | AGL1: 44773 | AGM1: 44774 | AGN1: 44775 | AGO1: 44776 | AGP1: 44777 | AGQ1: 44778 | AGR1: 44779 | AGS1: 44780 | AGT1: 44781 | AGU1: 44782 | AGV1: 44783 | AGW1: 44784 | AGX1: 44785 | AGY1: 44786 | AGZ1: 44787 | AHA1: 44788 | AHB1: 44789 | AHC1: 44790 | AHD1: 44791 | AHE1: 44792 | AHF1: 44793 | AHG1: 44794 | AHH1: 44795 | AHI1: 44796 | AHJ1: 44797 | AHK1: 44798 | AHL1: 44799 | AHM1: 44800 | AHN1: 44801 | AHO1: 44802 | AHP1: 44803 | AHQ1: 44804 | AHR1: 44805 | AHS1: 44806 | AHT1: 44807 | AHU1: 44808 | AHV1: 44809 | AHW1: 44810 | AHX1: 44811 | AHY1: 44812 | AHZ1: 44813 | AIA1: 44814 | AIB1: 44815 | AIC1: 44816 | AID1: 44817 | AIE1: 44818 | AIF1: 44819 | AIG1: 44820 | AIH1: 44821 | AII1: 44822 | AIJ1: 44823 | AIK1: 44824 | AIL1: 44825 | AIM1: 44826 | AIN1: 44827 | AIO1: 44828 | AIP1: 44829 | AIQ1: 44830 | AIR1: 44831 | AIS1: 44832 | AIT1: 44833 | AIU1: 44834 | AIV1: 44835 | AIW1: 44836 | AIX1: 44837 | AIY1: 44838 | AIZ1: 44839 | AJA1: 44840 | AJB1: 44841 | AJC1: 44842 | AJD1: 44843 | AJE1: 44844 | AJF1: 44845 | AJG1: 44846 | AJH1: 44847 | AJI1: 44848 | AJJ1: 44849 | AJK1: 44850 | AJL1: 44851 | AJM1: 44852 | AJN1: 44853 | AJO1: 44854 | AJP1: 44855 | AJQ1: 44856 | AJR1: 44857 | AJS1: 44858 | AJT1: 44859 | AJU1: 44860 | AJV1: 44861 | AJW1: 44862 | AJX1: 44863 | AJY1: 44864 | AJZ1: 44865 | AKA1: 44866 | AKB1: 44867 | AKC1: 44868 | AKD1: 44869 | AKE1: 44870 | AKF1: 44871 | AKG1: 44872 | AKH1: 44873 | AKI1: 44874 | AKJ1: 44875 | AKK1: 44876 | AKL1: 44877 | AKM1: 44878 | AKN1: 44879 | AKO1: 44880 | AKP1: 44881 | AKQ1: 44882 | AKR1: 44883 | AKS1: 44884 | AKT1: 44885 | AKU1: 44886 | AKV1: 44887 | AKW1: 44888 | AKX1: 44889 | AKY1: 44890 | AKZ1: 44891 | ALA1: 44892 | ALB1: 44893 | ALC1: 44894 | ALD1: 44895 | ALE1: 44896 | ALF1: 44897 | ALG1: 44898 | ALH1: 44899 | ALI1: 44900 | ALJ1: 44901 | ALK1: 44902 | ALL1: 44903 | ALM1: 44904 | ALN1: 44905 | ALO1: 44906 | ALP1: 44907 | ALQ1: 44908 | ALR1: 44909 | ALS1: 44910 | ALT1: 44911 | ALU1: 44912 | ALV1: 44913 | ALW1: 44914 | ALX1: 44915 | ALY1: 44916 | ALZ1: 44917 | AMA1: 44918 | AMB1: 44919 | AMC1: 44920 | AMD1: 44921 | AME1: 44922 | AMF1: 44923 | AMG1: 44924 | AMH1: 44925 | AMI1: 44926 | AMJ1: 44927 | AMK1: 44928 | AML1: 44929 | AMM1: 44930 | AMN1: 44931 | AMO1: 44932 | AMP1: 44933 | AMQ1: 44934 | AMR1: 44935 | AMS1: 44936 | AMT1: 44937 | AMU1: 44938 | AMV1: 44939 | AMW1: 44940 | AMX1: 44941 | AMY1: 44942 | AMZ1: 44943 | ANA1: 44944 | ANB1: 44945 | ANC1: 44946 | AND1: 44947 | ANE1: 44948 | ANF1: 44949 | ANG1: 44950 | ANH1: 44951 | ANI1: 44952 | ANJ1: 44953 | ANK1: 44954 | ANL1: 44955 | ANM1: 44956 | ANN1: 44957 | ANO1: 44958 | ANP1: 44959 | ANQ1: 44960 | ANR1: 44961 | ANS1: 44962 | ANT1: 44963 | ANU1: 44964 | ANV1: 44965 | ANW1: 44966 | ANX1: 44967 | ANY1: 44968 | ANZ1: 44969 | AOA1: 44970 | AOB1: 44971 | AOC1: 44972 | AOD1: 44973 | AOE1: 44974 | AOF1: 44975 | AOG1: 44976 | AOH1: 44977 | AOI1: 44978 | AOJ1: 44979 | AOK1: 44980 | AOL1: 44981 | AOM1: 44982 | AON1: 44983 | AOO1: 44984 | AOP1: 44985 | AOQ1: 44986 | AOR1: 44987 | AOS1: 44988 | AOT1: 44989 | AOU1: 44990 | AOV1: 44991 | AOW1: 44992 | AOX1: 44993 | AOY1: 44994 | AOZ1: 44995 | APA1: 44996 | APB1: 44997 | APC1: 44998 | APD1: 44999 | APE1: 45000 | APF1: 45001 | APG1: 45002 | APH1: 45003 | API1: 45004 | APJ1: 45005 | APK1: 45006 | APL1: 45007 | APM1: 45008 | APN1: 45009 | APO1: 45010 | APP1: 45011 | APQ1: 45012 | APR1: 45013 | APS1: 45014 | APT1: 45015 | APU1: 45016 | APV1: 45017 | APW1: 45018 | APX1: 45019 | APY1: 45020 | APZ1: 45021 | AQA1: 45022 | AQB1: 45023 | AQC1: 45024 | AQD1: 45025 | AQE1: 45026 | AQF1: 45027 | AQG1: 45028 | AQH1: 45029 | AQI1: 45030 | AQJ1: 45031 | AQK1: 45032 | AQL1: 45033 | AQM1: 45034 | AQN1: 45035 | AQO1: 45036 | AQP1: 45037 | AQQ1: 45038 | AQR1: 45039 | AQS1: 45040 | AQT1: 45041 | AQU1: 45042 | AQV1: 45043 | AQW1: 45044 | AQX1: 45045 | AQY1: 45046 | AQZ1: 45047 | ARA1: 45048 | ARB1: 45049 | ARC1: 45050 | ARD1: 45051 | ARE1: 45052 | ARF1: 45053 | ARG1: 45054 | ARH1: 45055 | ARI1: 45056 | ARJ1: 45057 | ARK1: 45058 | ARL1: 45059 | ARM1: 45060 | ARN1: 45061 | ARO1: 45062 | ARP1: 45063 | ARQ1: 45064 | ARR1: 45065 | ARS1: 45066 | ART1: 45067 | ARU1: 45068 | ARV1: 45069 | ARW1: 45070 | ARX1: 45071 | ARY1: 45072 | ARZ1: 45073 | ASA1: 45074 | ASB1: 45075 | ASC1: 45076 | ASD1: 45077 | ASE1: 45078 | ASF1: 45079 | ASG1: 45080 | ASH1: 45081 | ASI1: 45082 | ASJ1: 45083 | ASK1: 45084 | ASL1: 45085 | ASM1: 45086 | ASN1: 45087 | ASO1: 45088 | ASP1: 45089 | ASQ1: 45090 | ASR1: 45091 | ASS1: 45092 | AST1: 45093 | ASU1: 45094 | ASV1: 45095 | ASW1: 45096 | ASX1: 45097 | ASY1: 45098 | ASZ1: 45099 | ATA1: 45100
A2: 01 | B2: 1434635 | C2: AGUASCALIENTES | D2: 0 | E2: 0 | F2: 0 | G2: 0 | H2: 0 | I2: 0 | J2: 0 | K2: 0 | L2: 0 | M2: 0 | N2: 0 | O2: 0 | P2: 0 | Q2: 0 | R2: 0 | S2: 0 | T2: 0 | U2: 0 | V2: 0 | W2: 0 | X2: 0 | Y2: 0 | Z2: 0 | AA2: 0 | AB2: 1 | AC2: 0 | AD2: 0 | AE2: 1 | AF2: 0 | AG2: 0 | AH2: 0 | AI2: 1 | AJ2: 0 | AK2: 1 | AL2: 0 | AM2: 0 | AN2: 1 | AO2: 0 | AP2: 0 | AQ2: 0 | AR2: 0 | AS2: 1 | AT2: 1 | AU2: 0 | AV2: 1 | AW2: 0 | AX2: 0 | AY2: 0 | AZ2: 1 | BA2: 0 | BB2: 3 | BC2: 3 | BD2: 1 | BE2: 0 | BF2: 1 | BG2: 0 | BH2: 0 | BI2: 2 | BJ2: 1 | BK2: 1 | BL2: 1 | BM2: 4 | BN2: 0 | BO2: 0 | BP2: 0 | BQ2: 2 | BR2: 1 | BS2: 0 | BT2: 4 | BU2: 1 | BV2: 1 | BW2: 4 | BX2: 3 | BY2: 3 | BZ2: 2 | CA2: 2 | CB2: 2 | CC2: 3 | CD2: 4 | CE2: 4 | CF2: 2 | CG2: 5 | CH2: 4 | CI2: 2 | CJ2: 4 | CK2: 6 | CL2: 3 | CM2: 7 | CN2: 2 | CO2: 3 | CP2: 3 | CQ2: 5 | CR2: 4 | CS2: 6 | CT2: 5 | CU2: 4 | CV2: 4 | CW2: 1 | CX2: 2 | CY2: 6 | CZ2: 5 | DA2: 10 | DB2: 4 | DC2: 1 | DD2: 4 | DE2: 2 | DF2: 2 | DG2: 4 | DH2: 4 | DI2: 8 | DJ2: 4 | DK2: 2 | DL2: 6 | DM2: 6 | DN2: 3 | DO2: 2 | DP2: 6 | DQ2: 4 | DR2: 3 | DS2: 5 | DT2: 3 | DU2: 3 | DV2: 2 | DW2: 3 | DX2: 2 | DY2: 5 | DZ2: 2 | EA2: 2 | EB2: 8 | EC2: 10 | ED2: 5 | EE2: 4 | EF2: 3 | EG2: 3 | EH2: 3 | EI2: 3 | EJ2: 4 | EK2: 3 | EL2: 2 | EM2: 2 | EN2: 6 | EO2: 2 | EP2: 6 | EQ2: 7 | ER2: 5 | ES2: 5 | ET2: 3 | EU2: 5 | EV2: 5 | EW2: 5 | EX2: 6 | EY2: 8 | EZ2: 6 | FA2: 4 | FB2: 5 | FC2: 4 | FD2: 5 | FE2: 6 | FF2: 3 | FG2: 2 | FH2: 16 | FI2: 7 | FJ2: 5 | FK2: 11 | FL2: 6 | FM2: 4 | FN2: 5 | FO2: 10 | FP2: 7 | FQ2: 13 | FR2: 6 | FS2: 8 | FT2: 12 | FU2: 7 | FV2: 8 | FW2: 9 | FX2: 7 | FY2: 2 | FZ2: 6 | GA2: 6 | GB2: 4 | GC2: 9 | GD2: 5 | GE2: 7 | GF2: 7 | GG2: 8 | GH2: 5 | GI2: 8 | GJ2: 12 | GK2: 6 | GL2: 4 | GM2: 7 | GN2: 5 | GO2: 3 | GP2: 8 | GQ2: 10 | GR2: 7 | GS2: 5 | GT2: 11 | GU2: 1 | GV2: 3 | GW2: 8 | GX2: 9 | GY2: 5 | GZ2: 2 | HA2: 7 | HB2: 4 | HC2: 6 | HD2: 3 | HE2: 8 | HF2: 8 | HG2: 3 | HH2: 6 | HI2: 3 | HJ2: 13 | HK2: 5 | HL2: 11 | HM2: 11 | HN2: 11 | HO2: 11 | HP2: 7 | HQ2: 10 | HR2: 7 | HS2: 3 | HT2: 4 | HU2: 5 | HV2: 9 | HW2: 7 | HX2: 7 | HY2: 6 | HZ2: 15 | IA2: 13 | IB2: 6 | IC2: 11 | ID2: 19 | IE2: 12 | IF2: 11 | IG2: 10 | IH2: 10 | II2: 13 | IJ2: 19 | IK2: 11 | IL2: 21 | IM2: 23 | IN2: 12 | IO2: 12 | IP2: 11 | IQ2: 9 | IR2: 12 | IS2: 20 | IT2: 11 | IU2: 11 | IV2: 14 | IW2: 12 | IX2: 15 | IY2: 8 | IZ2: 7 | JA2: 18 | JB2: 18 | JC2: 24 | JD2: 17 | JE2: 11 | JF2: 11 | JG2: 23 | JH2: 15 | JI2: 10 | JJ2: 17 | JK2: 8 | JL2: 11 | JM2: 11 | JN2: 11 | JO2: 15 | JP2: 13 | JQ2: 4 | JR2: 9 | JS2: 8 | JT2: 10 | JU2: 6 | JV2: 11 | JW2: 13 | JX2: 11 | JY2: 4 | JZ2: 5 | KA2: 11 | KB2: 10 | KC2: 8 | KD2: 10 | KE2: 10 | KF2: 11 | KG2: 7 | KH2: 4 | KI2: 5 | KJ2: 9 | KK2: 5 | KL2: 7 | KM2: 8 | KN2: 8 | KO2: 6 | KP2: 6 | KQ2: 10 | KR2: 16 | KS2: 10 | KT2: 8 | KU2: 9 | KV2: 12 | KW2: 12 | KX2: 15 | KY2: 6 | KZ2: 15 | LA2: 14 | LB2: 10 | LC2: 12 | LD2: 11 | LE2: 11 | LF2: 18 | LG2: 14 | LH2: 12 | LI2: 14 | LJ2: 14 | LK2: 15 | LL2: 8 | LM2: 21 | LN2: 16 | LO2: 5 | LP2: 17 | LQ2: 16 | LR2: 17 | LS2: 9 | LT2: 8 | LU2: 10 | LV2: 16 | LW2: 12 | LX2: 4 | LY2: 9 | LZ2: 9 | MA2: 11 | MB2: 8 | MC2: 4 | MD2: 10 | ME2: 10 | MF2: 9 | MG2: 5 | MH2: 8 | MI2: 6 | MJ2: 5 | MK2: 6 | ML2: 4 | MM2: 8 | MN2: 8 | MO2: 6 | MP2: 1 | MQ2: 4 | MR2: 6 | MS2: 6 | MT2: 6 | MU2: 5 | MV2: 5 | MW2: 3 | MX2: 6 | MY2: 7 | MZ2: 3 | NA2: 4 | NB2: 3 | NC2: 6 | ND2: 1 | NE2: 3 | NF2: 1 | NG2: 2 | NH2: 4 | NI2: 5 | NJ2: 4 | NK2: 2 | NL2: 1 | NM2: 2 | NN2: 3 | NO2: 1 | NP2: 2 | NQ2: 3 | NR2: 2 | NS2: 3 | NT2: 8 | NU2: 2 | NV2: 2 | NW2: 6 | NX2: 3 | NY2: 3 | NZ2: 4 | OA2: 3 | OB2: 4 | OC2: 3 | OD2: 3 | OE2: 3 | OF2: 5 | OG2: 2 | OH2: 9 | OI2: 6 | OJ2: 5 | OK2: 6 | OL2: 5 | OM2: 10 | ON2: 3 | OO2: 3 | OP2: 1 | OQ2: 2 | OR2: 5 | OS2: 3 | OT2: 4 | OU2: 2 | OV2: 3 | OW2: 1 | OX2: 5 | OY2: 4 | OZ2: 1 | PA2: 0 | PB2: 4 | PC2: 1 | PD2: 1 | PE2: 2 | PF2: 4 | PG2: 0 | PH2: 0 | PI2: 5 | PJ2: 1 | PK2: 1 | PL2: 0 | PM2: 2 | PN2: 0 | PO2: 1 | PP2: 1 | PQ2: 2 | PR2: 0 | PS2: 2 | PT2: 4 | PU2: 1 | PV2: 1 | PW2: 2 | PX2: 0 | PY2: 0 | PZ2: 0 | QA2: 1 | QB2: 0 | QC2: 1 | QD2: 2 | QE2: 2 | QF2: 4 | QG2: 1 | QH2: 0 | QI2: 1 | QJ2: 1 | QK2: 0 | QL2: 0 | QM2: 1 | QN2: 1 | QO2: 2 | QP2: 1 | QQ2: 3 | QR2: 0 | QS2: 0 | QT2: 0 | QU2: 0 | QV2: 1 | QW2: 0 | QX2: 0 | QY2: 0 | QZ2: 0 | RA2: 1 | RB2: 1 | RC2: 0 | RD2: 0 | RE2: 0 | RF2: 0 | RG2: 0 | RH2: 0 | RI2: 0 | RJ2: 0 | RK2: 1 | RL2: 0 | RM2: 0 | RN2: 1 | RO2: 0 | RP2: 0 | RQ2: 1 | RR2: 1 | RS2: 0 | RT2: 0 | RU2: 1 | RV2: 1 | RW2: 0 | RX2: 2 | RY2: 0 | RZ2: 0 | SA2: 2 | SB2: 0 | SC2: 1 | SD2: 2 | SE2: 1 | SF2: 0 | SG2: 0 | SH2: 1 | SI2: 2 | SJ2: 2 | SK2: 0 | SL2: 0 | SM2: 4 | SN2: 1 | SO2: 2 | SP2: 1 | SQ2: 2 | SR2: 6 | SS2: 3 | ST2: 3 | SU2: 2 | SV2: 5 | SW2: 5 | SX2: 5 | SY2: 4 | SZ2: 1 | TA2: 5 | TB2: 5 | TC2: 4 | TD2: 3 | TE2: 5 | TF2: 2 | TG2: 6 | TH2: 2 | TI2: 11 | TJ2: 5 | TK2: 8 | TL2: 5 | TM2: 8 | TN2: 11 | TO2: 5 | TP2: 13 | TQ2: 5 | TR2: 3 | TS2: 2 | TT2: 2 | TU2: 6 | TV2: 6 | TW2: 2 | TX2: 6 | TY2: 13 | TZ2: 8 | UA2: 6 | UB2: 2 | UC2: 4 | UD2: 7 | UE2: 5 | UF2: 5 | UG2: 6 | UH2: 6 | UI2: 3 | UJ2: 8 | UK2: 5 | UL2: 4 | UM2: 4 | UN2: 6 | UO2: 9 | UP2: 2 | UQ2: 4 | UR2: 6 | US2: 5 | UT2: 8 | UU2: 2 | UV2: 3 | UW2: 5 | UX2: 3 | UY2: 6 | UZ2: 3 | VA2: 11 | VB2: 2 | VC2: 6 | VD2: 1 | VE2: 4 | VF2: 4 | VG2: 4 | VH2: 4 | VI2: 3 | VJ2: 2 | VK2: 4 | VL2: 5 | VM2: 2 | VN2: 4 | VO2: 5 | VP2: 1 | VQ2: 6 | VR2: 4 | VS2: 2 | VT2: 3 | VU2: 6 | VV2: 4 | VW2: 2 | VX2: 1 | VY2: 3 | VZ2: 4 | WA2: 5 | WB2: 6 | WC2: 3 | WD2: 0 | WE2: 2 | WF2: 0 | WG2: 4 | WH2: 2 | WI2: 2 | WJ2: 2 | WK2: 1 | WL2: 3 | WM2: 2 | WN2: 1 | WO2: 2 | WP2: 2 | WQ2: 2 | WR2: 3 | WS2: 2 | WT2: 0 | WU2: 3 | WV2: 2 | WW2: 3 | WX2: 0 | WY2: 3 | WZ2: 5 | XA2: 2 | XB2: 2 | XC2: 0 | XD2: 3 | XE2: 2 | XF2: 2 | XG2: 1 | XH2: 2 | XI2: 4 | XJ2: 1 | XK2: 5 | XL2: 3 | XM2: 0 | XN2: 3 | XO2: 1 | XP2: 4 | XQ2: 3 | XR2: 1 | XS2: 3 | XT2: 6 | XU2: 3 | XV2: 1 | XW2: 6 | XX2: 4 | XY2: 2 | XZ2: 3 | YA2: 2 | YB2: 4 | YC2: 3 | YD2: 5 | YE2: 4 | YF2: 3 | YG2: 9 | YH2: 1 | YI2: 1 | YJ2: 2 | YK2: 4 | YL2: 4 | YM2: 4 | YN2: 8 | YO2: 3 | YP2: 3 | YQ2: 7 | YR2: 10 | YS2: 9 | YT2: 10 | YU2: 6 | YV2: 12 | YW2: 6 | YX2: 8 | YY2: 6 | YZ2: 9 | ZA2: 3 | ZB2: 10 | ZC2: 18 | ZD2: 15 | ZE2: 14 | ZF2: 10 | ZG2: 12 | ZH2: 8 | ZI2: 12 | ZJ2: 15 | ZK2: 7 | ZL2: 5 | ZM2: 12 | ZN2: 9 | ZO2: 10 | ZP2: 16 | ZQ2: 8 | ZR2: 11 | ZS2: 5 | ZT2: 12 | ZU2: 11 | ZV2: 10 | ZW2: 1 | ZX2: 7 | ZY2: 6 | ZZ2: 2 | AAA2: 9 | AAB2: 2 | AAC2: 5 | AAD2: 5 | AAE2: 2 | AAF2: 3 | AAG2: 0 | AAH2: 3 | AAI2: 0 | AAJ2: 3 | AAK2: 1 | AAL2: 1 | AAM2: 1 | AAN2: 2 | AAO2: 0 | AAP2: 0 | AAQ2: 2 | AAR2: 1 | AAS2: 2 | AAT2: 0 | AAU2: 3 | AAV2: 1 | AAW2: 0 | AAX2: 1 | AAY2: 3 | AAZ2: 1 | ABA2: 0 | ABB2: 0 | ABC2: 2 | ABD2: 0 | ABE2: 0 | ABF2: 0 | ABG2: 2 | ABH2: 1 | ABI2: 0 | ABJ2: 0 | ABK2: 0 | ABL2: 2 | ABM2: 2 | ABN2: 1 | ABO2: 1 | ABP2: 0 | ABQ2: 0 | ABR2: 0 | ABS2: 0 | ABT2: 0 | ABU2: 0 | ABV2: 1 | ABW2: 0 | ABX2: 0 | ABY2: 0 | ABZ2: 0 | ACA2: 0 | ACB2: 0 | ACC2: 0 | ACD2: 0 | ACE2: 0 | ACF2: 0 | ACG2: 0 | ACH2: 0 | ACI2: 0 | ACJ2: 0 | ACK2: 1 | ACL2: 0 | ACM2: 0 | ACN2: 0 | ACO2: 0 | ACP2: 1 | ACQ2: 1 | ACR2: 0 | ACS2: 0 | ACT2: 0 | ACU2: 0 | ACV2: 0 | ACW2: 0 | ACX2: 0 | ACY2: 0 | ACZ2: 0 | ADA2: 1 | ADB2: 0 | ADC2: 0 | ADD2: 0 | ADE2: 0 | ADF2: 0 | ADG2: 1 | ADH2: 0 | ADI2: 0 | ADJ2: 0 | ADK2: 0 | ADL2: 0 | ADM2: 0 | ADN2: 0 | ADO2: 0 | ADP2: 0 | ADQ2: 0 | ADR2: 0 | ADS2: 0 | ADT2: 0 | ADU2: 0 | ADV2: 0 | ADW2: 0 | ADX2: 0 | ADY2: 0 | ADZ2: 0 | AEA2: 0 | AEB2: 0 | AEC2: 0 | AED2: 0 | AEE2: 0 | AEF2: 1 | AEG2: 0 | AEH2: 1 | AEI2: 1 | AEJ2: 0 | AEK2: 0 | AEL2: 0 | AEM2: 0 | AEN2: 0 | AEO2: 0 | AEP2: 0 | AEQ2: 1 | AER2: 0 | AES2: 0 | AET2: 0 | AEU2: 1 | AEV2: 0 | AEW2: 1 | AEX2: 0 | AEY2: 1 | AEZ2: 0 | AFA2: 0 | AFB2: 0 | AFC2: 0 | AFD2: 1 | AFE2: 1 | AFF2: 0 | AFG2: 0 | AFH2: 0 | AFI2: 0 | AFJ2: 0 | AFK2: 0 | AFL2: 0 | AFM2: 1 | AFN2: 1 | AFO2: 1 | AFP2: 0 | AFQ2: 0 | AFR2: 2 | AFS2: 0 | AFT2: 2 | AFU2: 2 | AFV2: 0 | AFW2: 2 | AFX2: 0 | AFY2: 1 | AFZ2: 0 | AGA2: 0 | AGB2: 0 | AGC2: 1 | AGD2: 0 | AGE2: 2 | AGF2: 1 | AGG2: 1 | AGH2: 2 | AGI2: 0 | AGJ2: 1 | AGK2: 1 | AGL2: 1 | AGM2: 0 | AGN2: 0 | AGO2: 0 | AGP2: 2 | AGQ2: 1 | AGR2: 1 | AGS2: 0 | AGT2: 0 | AGU2: 1 | AGV2: 1 | AGW2: 0 | AGX2: 2 | AGY2: 0 | AGZ2: 1 | AHA2: 1 | AHB2: 2 | AHC2: 0 | AHD2: 1 | AHE2: 0 | AHF2: 1 | AHG2: 1 | AHH2: 0 | AHI2: 1 | AHJ2: 2 | AHK2: 1 | AHL2: 0 | AHM2: 2 | AHN2: 0 | AHO2: 0 | AHP2: 3 | AHQ2: 0 | AHR2: 0 | AHS2: 0 | AHT2: 0 | AHU2: 0 | AHV2: 1 | AHW2: 0 | AHX2: 0 | AHY2: 0 | AHZ2: 0 | AIA2: 1 | AIB2: 0 | AIC2: 0 | AID2: 0 | AIE2: 1 | AIF2: 0 | AIG2: 1 | AIH2: 0 | AII2: 0 | AIJ2: 0 | AIK2: 0 | AIL2: 0 | AIM2: 1 | AIN2: 0 | AIO2: 0 | AIP2: 0 | AIQ2: 0 | AIR2: 0 | AIS2: 0 | AIT2: 0 | AIU2: 0 | AIV2: 0 | AIW2: 0 | AIX2: 0 | AIY2: 0 | AIZ2: 1 | AJA2: 0 | AJB2: 0 | AJC2: 0 | AJD2: 0 | AJE2: 0 | AJF2: 0 | AJG2: 0 | AJH2: 0 | AJI2: 0 | AJJ2: 0 | AJK2: 0 | AJL2: 0 | AJM2: 0 | AJN2: 0 | AJO2: 0 | AJP2: 0 | AJQ2: 0 | AJR2: 0 | AJS2: 1 | AJT2: 0 | AJU2: 0 | AJV2: 0 | AJW2: 0 | AJX2: 0 | AJY2: 0 | AJZ2: 0 | AKA2: 0 | AKB2: 0 | AKC2: 0 | AKD2: 0 | AKE2: 0 | AKF2: 0 | AKG2: 0 | AKH2: 0 | AKI2: 0 | AKJ2: 0 | AKK2: 0 | AKL2: 0 | AKM2: 0 | AKN2: 0 | AKO2: 0 | AKP2: 0 | AKQ2: 0 | AKR2: 0 | AKS2: 0 | AKT2: 0 | AKU2: 0 | AKV2: 0 | AKW2: 0 | AKX2: 0 | AKY2: 0 | AKZ2: 0 | ALA2: 0 | ALB2: 0 | ALC2: 0 | ALD2: 1 | ALE2: 0 | ALF2: 0 | ALG2: 0 | ALH2: 0 | ALI2: 0 | ALJ2: 0 | ALK2: 0 | ALL2: 0 | ALM2: 0 | ALN2: 0 | ALO2: 0 | ALP2: 0 | ALQ2: 0 | ALR2: 0 | ALS2: 0 | ALT2: 2 | ALU2: 0 | ALV2: 0 | ALW2: 0 | ALX2: 1 | ALY2: 0 | ALZ2: 1 | AMA2: 1 | AMB2: 0 | AMC2: 0 | AMD2: 0 | AME2: 0 | AMF2: 0 | AMG2: 1 | AMH2: 0 | AMI2: 0 | AMJ2: 2 | AMK2: 0 | AML2: 1 | AMM2: 0 | AMN2: 0 | AMO2: 0 | AMP2: 0 | AMQ2: 0 | AMR2: 1 | AMS2: 0 | AMT2: 1 | AMU2: 0 | AMV2: 0 | AMW2: 1 | AMX2: 1 | AMY2: 1 | AMZ2: 1 | ANA2: 2 | ANB2: 0 | ANC2: 1 | AND2: 0 | ANE2: 1 | ANF2: 1 | ANG2: 1 | ANH2: 1 | ANI2: 0 | ANJ2: 1 | ANK2: 1 | ANL2: 0 | ANM2: 2 | ANN2: 0 | ANO2: 0 | ANP2: 1 | ANQ2: 0 | ANR2: 1 | ANS2: 0 | ANT2: 2 | ANU2: 2 | ANV2: 2 | ANW2: 1 | ANX2: 0 | ANY2: 1 | ANZ2: 1 | AOA2: 1 | AOB2: 0 | AOC2: 0 | AOD2: 0 | AOE2: 0 | AOF2: 0 | AOG2: 1 | AOH2: 0 | AOI2: 1 | AOJ2: 0 | AOK2: 0 | AOL2: 1 | AOM2: 0 | AON2: 0 | AOO2: 1 | AOP2: 0 | AOQ2: 0 | AOR2: 0 | AOS2: 0 | AOT2: 0 | AOU2: 0 | AOV2: 0 | AOW2: 0 | AOX2: 0 | AOY2: 0 | AOZ2: 0 | APA2: 0 | APB2: 0 | APC2: 0 | APD2: 0 | APE2: 0 | APF2: 0 | APG2: 0 | APH2: 0 | API2: 0 | APJ2: 0 | APK2: 0 | APL2: 0 | APM2: 0 | APN2: 0 | APO2: 0 | APP2: 0 | APQ2: 0 | APR2: 0 | APS2: 0 | APT2: 0 | APU2: 0 | APV2: 0 | APW2: 0 | APX2: 1 | APY2: 0 | APZ2: 0 | AQA2: 0 | AQB2: 0 | AQC2: 0 | AQD2: 0 | AQE2: 0 | AQF2: 0 | AQG2: 1 | AQH2: 1 | AQI2: 0 | AQJ2: 0 | AQK2: 0 | AQL2: 0 | AQM2: 0 | AQN2: 0 | AQO2: 0 | AQP2: 0 | AQQ2: 0 | AQR2: 0 | AQS2: 0 | AQT2: 0 | AQU2: 0 | AQV2: 0 | AQW2: 0 | AQX2: 0 | AQY2: 0 | AQZ2: 0 | ARA2: 0 | ARB2: 0 | ARC2: 0 | ARD2: 0 | ARE2: 0 | ARF2: 0 | ARG2: 0 | ARH2: 0 | ARI2: 0 | ARJ2: 0 | ARK2: 0 | ARL2: 0 | ARM2: 0 | ARN2: 0 | ARO2: 1 | ARP2: 0 | ARQ2: 0 | ARR2: 0 | ARS2: 0 | ART2: 0 | ARU2: 0 | ARV2: 0 | ARW2: 0 | ARX2: 0 | ARY2: 0 | ARZ2: 0 | ASA2: 0 | ASB2: 0 | ASC2: 0 | ASD2: 0 | ASE2: 0 | ASF2: 0 | ASG2: 0 | ASH2: 0 | ASI2: 0 | ASJ2: 0 | ASK2: 0 | ASL2: 0 | ASM2: 0 | ASN2: 0 | ASO2: 0 | ASP2: 0 | ASQ2: 0 | ASR2: 0 | ASS2: 0 | AST2: 0 | ASU2: 0 | ASV2: 0 | ASW2: 0 | ASX2: 1 | ASY2: 0 | ASZ2: 0 | ATA2: 0
A3: 02 | B3: 3634868 | C3: BAJA CALIFORNIA | D3: 0 | E3: 0 | F3: 0 | G3: 0 | H3: 0 | I3: 0 | J3: 0 | K3: 0 | L3: 0 | M3: 0 | N3: 0 | O3: 0 | P3: 1 | Q3: 2 | R3: 2 | S3: 2 | T3: 5 | U3: 2 | V3: 9 | W3: 1 | X3: 12 | Y3: 5 | Z3: 7 | AA3: 7 | AB3: 11 | AC3: 14 | AD3: 20 | AE3: 14 | AF3: 20 | AG3: 22 | AH3: 18 | AI3: 30 | AJ3: 20 | AK3: 32 | AL3: 27 | AM3: 25 | AN3: 35 | AO3: 32 | AP3: 33 | AQ3: 34 | AR3: 28 | AS3: 43 | AT3: 44 | AU3: 45 | AV3: 35 | AW3: 33 | AX3: 38 | AY3: 27 | AZ3: 42 | BA3: 47 | BB3: 40 | BC3: 31 | BD3: 38 | BE3: 41 | BF3: 34 | BG3: 36 | BH3: 31 | BI3: 41 | BJ3: 41 | BK3: 30 | BL3: 34 | BM3: 45 | BN3: 52 | BO3: 34 | BP3: 41 | BQ3: 23 | BR3: 28 | BS3: 30 | BT3: 35 | BU3: 42 | BV3: 37 | BW3: 35 | BX3: 40 | BY3: 22 | BZ3: 34 | CA3: 33 | CB3: 37 | CC3: 32 | CD3: 32 | CE3: 33 | CF3: 26 | CG3: 40 | CH3: 32 | CI3: 36 | CJ3: 24 | CK3: 33 | CL3: 28 | CM3: 33 | CN3: 30 | CO3: 35 | CP3: 25 | CQ3: 21 | CR3: 30 | CS3: 25 | CT3: 27 | CU3: 15 | CV3: 25 | CW3: 23 | CX3: 26 | CY3: 27 | CZ3: 27 | DA3: 27 | DB3: 22 | DC3: 18 | DD3: 30 | DE3: 32 | DF3: 22 | DG3: 25 | DH3: 29 | DI3: 31 | DJ3: 38 | DK3: 45 | DL3: 32 | DM3: 25 | DN3: 23 | DO3: 31 | DP3: 26 | DQ3: 24 | DR3: 19 | DS3: 23 | DT3: 9 | DU3: 26 | DV3: 27 | DW3: 18 | DX3: 25 | DY3: 28 | DZ3: 20 | EA3: 22 | EB3: 23 | EC3: 16 | ED3: 29 | EE3: 17 | EF3: 24 | EG3: 21 | EH3: 18 | EI3: 25 | EJ3: 16 | EK3: 16 | EL3: 18 | EM3: 23 | EN3: 33 | EO3: 16 | EP3: 13 | EQ3: 15 | ER3: 20 | ES3: 7 | ET3: 17 | EU3: 23 | EV3: 6 | EW3: 12 | EX3: 22 | EY3: 14 | EZ3: 19 | FA3: 28 | FB3: 22 | FC3: 12 | FD3: 11 | FE3: 13 | FF3: 16 | FG3: 13 | FH3: 17 | FI3: 11 | FJ3: 13 | FK3: 11 | FL3: 15 | FM3: 9 | FN3: 23 | FO3: 15 | FP3: 18 | FQ3: 17 | FR3: 9 | FS3: 13 | FT3: 14 | FU3: 7 | FV3: 21 | FW3: 11 | FX3: 17 | FY3: 9 | FZ3: 9 | GA3: 12 | GB3: 8 | GC3: 18 | GD3: 11 | GE3: 11 | GF3: 13 | GG3: 12 | GH3: 13 | GI3: 11 | GJ3: 6 | GK3: 11 | GL3: 11 | GM3: 20 | GN3: 10 | GO3: 5 | GP3: 12 | GQ3: 11 | GR3: 8 | GS3: 12 | GT3: 6 | GU3: 7 | GV3: 8 | GW3: 7 | GX3: 11 | GY3: 12 | GZ3: 5 | HA3: 8 | HB3: 9 | HC3: 8 | HD3: 8 | HE3: 16 | HF3: 7 | HG3: 12 | HH3: 7 | HI3: 12 | HJ3: 7 | HK3: 11 | HL3: 11 | HM3: 11 | HN3: 11 | HO3: 9 | HP3: 15 | HQ3: 8 | HR3: 18 | HS3: 16 | HT3: 10 | HU3: 14 | HV3: 9 | HW3: 8 | HX3: 15 | HY3: 22 | HZ3: 23 | IA3: 10 | IB3: 16 | IC3: 18 | ID3: 15 | IE3: 10 | IF3: 17 | IG3: 13 | IH3: 15 | II3: 14 | IJ3: 13 | IK3: 16 | IL3: 12 | IM3: 15 | IN3: 12 | IO3: 14 | IP3: 18 | IQ3: 30 | IR3: 24 | IS3: 22 | IT3: 29 | IU3: 29 | IV3: 25 | IW3: 21 | IX3: 37 | IY3: 29 | IZ3: 24 | JA3: 32 | JB3: 38 | JC3: 39 | JD3: 28 | JE3: 36 | JF3: 40 | JG3: 35 | JH3: 40 | JI3: 27 | JJ3: 48 | JK3: 43 | JL3: 46 | JM3: 40 | JN3: 35 | JO3: 42 | JP3: 44 | JQ3: 55 | JR3: 40 | JS3: 54 | JT3: 65 | JU3: 56 | JV3: 53 | JW3: 61 | JX3: 57 | JY3: 53 | JZ3: 57 | KA3: 56 | KB3: 60 | KC3: 50 | KD3: 58 | KE3: 61 | KF3: 48 | KG3: 47 | KH3: 67 | KI3: 40 | KJ3: 42 | KK3: 48 | KL3: 57 | KM3: 63 | KN3: 51 | KO3: 48 | KP3: 43 | KQ3: 48 | KR3: 37 | KS3: 42 | KT3: 47 | KU3: 38 | KV3: 46 | KW3: 36 | KX3: 35 | KY3: 48 | KZ3: 40 | LA3: 44 | LB3: 48 | LC3: 33 | LD3: 24 | LE3: 41 | LF3: 36 | LG3: 27 | LH3: 33 | LI3: 20 | LJ3: 35 | LK3: 30 | LL3: 23 | LM3: 29 | LN3: 30 | LO3: 24 | LP3: 17 | LQ3: 23 | LR3: 23 | LS3: 16 | LT3: 22 | LU3: 21 | LV3: 23 | LW3: 25 | LX3: 19 | LY3: 13 | LZ3: 12 | MA3: 13 | MB3: 18 | MC3: 11 | MD3: 13 | ME3: 6 | MF3: 12 | MG3: 8 | MH3: 15 | MI3: 7 | MJ3: 10 | MK3: 12 | ML3: 8 | MM3: 5 | MN3: 7 | MO3: 6 | MP3: 9 | MQ3: 7 | MR3: 7 | MS3: 4 | MT3: 5 | MU3: 7 | MV3: 8 | MW3: 7 | MX3: 7 | MY3: 3 | MZ3: 2 | NA3: 3 | NB3: 6 | NC3: 3 | ND3: 2 | NE3: 10 | NF3: 10 | NG3: 5 | NH3: 4 | NI3: 7 | NJ3: 3 | NK3: 3 | NL3: 3 | NM3: 5 | NN3: 2 | NO3: 4 | NP3: 0 | NQ3: 9 | NR3: 1 | NS3: 3 | NT3: 4 | NU3: 3 | NV3: 4 | NW3: 5 | NX3: 5 | NY3: 3 | NZ3: 3 | OA3: 3 | OB3: 6 | OC3: 6 | OD3: 3 | OE3: 4 | OF3: 4 | OG3: 2 | OH3: 6 | OI3: 3 | OJ3: 3 | OK3: 2 | OL3: 5 | OM3: 9 | ON3: 4 | OO3: 2 | OP3: 5 | OQ3: 2 | OR3: 4 | OS3: 1 | OT3: 3 | OU3: 1 | OV3: 1 | OW3: 4 | OX3: 3 | OY3: 4 | OZ3: 3 | PA3: 3 | PB3: 4 | PC3: 6 | PD3: 6 | PE3: 4 | PF3: 4 | PG3: 6 | PH3: 3 | PI3: 3 | PJ3: 2 | PK3: 3 | PL3: 2 | PM3: 3 | PN3: 9 | PO3: 5 | PP3: 4 | PQ3: 1 | PR3: 2 | PS3: 2 | PT3: 9 | PU3: 1 | PV3: 2 | PW3: 2 | PX3: 3 | PY3: 4 | PZ3: 5 | QA3: 4 | QB3: 2 | QC3: 3 | QD3: 3 | QE3: 1 | QF3: 1 | QG3: 6 | QH3: 1 | QI3: 1 | QJ3: 3 | QK3: 5 | QL3: 5 | QM3: 4 | QN3: 1 | QO3: 3 | QP3: 2 | QQ3: 2 | QR3: 4 | QS3: 6 | QT3: 3 | QU3: 1 | QV3: 3 | QW3: 3 | QX3: 4 | QY3: 7 | QZ3: 3 | RA3: 4 | RB3: 1 | RC3: 3 | RD3: 4 | RE3: 4 | RF3: 0 | RG3: 3 | RH3: 2 | RI3: 0 | RJ3: 3 | RK3: 8 | RL3: 5 | RM3: 2 | RN3: 5 | RO3: 5 | RP3: 0 | RQ3: 2 | RR3: 3 | RS3: 0 | RT3: 2 | RU3: 1 | RV3: 3 | RW3: 4 | RX3: 5 | RY3: 9 | RZ3: 4 | SA3: 6 | SB3: 3 | SC3: 1 | SD3: 6 | SE3: 7 | SF3: 6 | SG3: 5 | SH3: 6 | SI3: 2 | SJ3: 6 | SK3: 4 | SL3: 11 | SM3: 6 | SN3: 1 | SO3: 4 | SP3: 4 | SQ3: 9 | SR3: 3 | SS3: 3 | ST3: 6 | SU3: 6 | SV3: 5 | SW3: 3 | SX3: 11 | SY3: 4 | SZ3: 4 | TA3: 11 | TB3: 6 | TC3: 6 | TD3: 5 | TE3: 9 | TF3: 8 | TG3: 9 | TH3: 6 | TI3: 5 | TJ3: 10 | TK3: 9 | TL3: 10 | TM3: 8 | TN3: 9 | TO3: 11 | TP3: 15 | TQ3: 9 | TR3: 10 | TS3: 10 | TT3: 9 | TU3: 8 | TV3: 5 | TW3: 11 | TX3: 15 | TY3: 10 | TZ3: 9 | UA3: 4 | UB3: 6 | UC3: 8 | UD3: 8 | UE3: 7 | UF3: 13 | UG3: 16 | UH3: 12 | UI3: 6 | UJ3: 10 | UK3: 19 | UL3: 10 | UM3: 12 | UN3: 9 | UO3: 13 | UP3: 12 | UQ3: 20 | UR3: 20 | US3: 10 | UT3: 10 | UU3: 8 | UV3: 9 | UW3: 12 | UX3: 6 | UY3: 11 | UZ3: 12 | VA3: 12 | VB3: 11 | VC3: 13 | VD3: 16 | VE3: 12 | VF3: 11 | VG3: 19 | VH3: 18 | VI3: 9 | VJ3: 12 | VK3: 9 | VL3: 6 | VM3: 15 | VN3: 14 | VO3: 13 | VP3: 20 | VQ3: 14 | VR3: 16 | VS3: 14 | VT3: 17 | VU3: 9 | VV3: 25 | VW3: 21 | VX3: 20 | VY3: 6 | VZ3: 15 | WA3: 23 | WB3: 18 | WC3: 27 | WD3: 11 | WE3: 11 | WF3: 19 | WG3: 32 | WH3: 25 | WI3: 22 | WJ3: 22 | WK3: 23 | WL3: 14 | WM3: 29 | WN3: 25 | WO3: 33 | WP3: 20 | WQ3: 14 | WR3: 18 | WS3: 25 | WT3: 20 | WU3: 32 | WV3: 17 | WW3: 23 | WX3: 12 | WY3: 25 | WZ3: 19 | XA3: 31 | XB3: 19 | XC3: 22 | XD3: 32 | XE3: 22 | XF3: 25 | XG3: 25 | XH3: 22 | XI3: 27 | XJ3: 25 | XK3: 31 | XL3: 35 | XM3: 20 | XN3: 27 | XO3: 27 | XP3: 23 | XQ3: 22 | XR3: 26 | XS3: 22 | XT3: 18 | XU3: 13 | XV3: 22 | XW3: 23 | XX3: 21 | XY3: 26 | XZ3: 17 | YA3: 24 | YB3: 24 | YC3: 15 | YD3: 23 | YE3: 22 | YF3: 18 | YG3: 12 | YH3: 16 | YI3: 18 | YJ3: 15 | YK3: 21 | YL3: 14 | YM3: 21 | YN3: 15 | YO3: 16 | YP3: 12 | YQ3: 33 | YR3: 25 | YS3: 20 | YT3: 17 | YU3: 28 | YV3: 16 | YW3: 13 | YX3: 11 | YY3: 22 | YZ3: 24 | ZA3: 20 | ZB3: 17 | ZC3: 26 | ZD3: 18 | ZE3: 22 | ZF3: 21 | ZG3: 24 | ZH3: 20 | ZI3: 17 | ZJ3: 23 | ZK3: 19 | ZL3: 26 | ZM3: 26 | ZN3: 24 | ZO3: 28 | ZP3: 21 | ZQ3: 23 | ZR3: 19 | ZS3: 19 | ZT3: 25 | ZU3: 19 | ZV3: 25 | ZW3: 15 | ZX3: 16 | ZY3: 19 | ZZ3: 11 | AAA3: 9 | AAB3: 11 | AAC3: 11 | AAD3: 12 | AAE3: 4 | AAF3: 7 | AAG3: 8 | AAH3: 6 | AAI3: 9 | AAJ3: 6 | AAK3: 12 | AAL3: 4 | AAM3: 4 | AAN3: 5 | AAO3: 9 | AAP3: 2 | AAQ3: 1 | AAR3: 2 | AAS3: 5 | AAT3: 2 | AAU3: 6 | AAV3: 3 | AAW3: 5 | AAX3: 1 | AAY3: 4 | AAZ3: 1 | ABA3: 1 | ABB3: 2 | ABC3: 3 | ABD3: 0 | ABE3: 0 | ABF3: 4 | ABG3: 0 | ABH3: 0 | ABI3: 1 | ABJ3: 1 | ABK3: 3 | ABL3: 1 | ABM3: 0 | ABN3: 0 | ABO3: 1 | ABP3: 1 | ABQ3: 0 | ABR3: 2 | ABS3: 2 | ABT3: 1 | ABU3: 2 | ABV3: 1 | ABW3: 0 | ABX3: 1 | ABY3: 1 | ABZ3: 0 | ACA3: 0 | ACB3: 2 | ACC3: 1 | ACD3: 1 | ACE3: 0 | ACF3: 0 | ACG3: 1 | ACH3: 1 | ACI3: 1 | ACJ3: 0 | ACK3: 1 | ACL3: 0 | ACM3: 2 | ACN3: 0 | ACO3: 0 | ACP3: 0 | ACQ3: 0 | ACR3: 0 | ACS3: 0 | ACT3: 1 | ACU3: 0 | ACV3: 0 | ACW3: 1 | ACX3: 0 | ACY3: 0 | ACZ3: 0 | ADA3: 0 | ADB3: 0 | ADC3: 0 | ADD3: 0 | ADE3: 0 | ADF3: 0 | ADG3: 0 | ADH3: 1 | ADI3: 0 | ADJ3: 0 | ADK3: 0 | ADL3: 1 | ADM3: 0 | ADN3: 0 | ADO3: 0 | ADP3: 0 | ADQ3: 2 | ADR3: 1 | ADS3: 0 | ADT3: 0 | ADU3: 0 | ADV3: 0 | ADW3: 1 | ADX3: 0 | ADY3: 0 | ADZ3: 0 | AEA3: 0 | AEB3: 1 | AEC3: 0 | AED3: 0 | AEE3: 0 | AEF3: 2 | AEG3: 0 | AEH3: 0 | AEI3: 0 | AEJ3: 0 | AEK3: 0 | AEL3: 0 | AEM3: 0 | AEN3: 0 | AEO3: 1 | AEP3: 1 | AEQ3: 1 | AER3: 0 | AES3: 0 | AET3: 0 | AEU3: 1 | AEV3: 0 | AEW3: 0 | AEX3: 1 | AEY3: 0 | AEZ3: 2 | AFA3: 1 | AFB3: 1 | AFC3: 0 | AFD3: 0 | AFE3: 1 | AFF3: 2 | AFG3: 1 | AFH3: 1 | AFI3: 0 | AFJ3: 0 | AFK3: 0 | AFL3: 1 | AFM3: 1 | AFN3: 0 | AFO3: 0 | AFP3: 1 | AFQ3: 1 | AFR3: 1 | AFS3: 3 | AFT3: 0 | AFU3: 2 | AFV3: 0 | AFW3: 3 | AFX3: 2 | AFY3: 1 | AFZ3: 3 | AGA3: 4 | AGB3: 4 | AGC3: 3 | AGD3: 3 | AGE3: 4 | AGF3: 0 | AGG3: 4 | AGH3: 4 | AGI3: 3 | AGJ3: 1 | AGK3: 2 | AGL3: 0 | AGM3: 2 | AGN3: 3 | AGO3: 2 | AGP3: 3 | AGQ3: 0 | AGR3: 3 | AGS3: 0 | AGT3: 1 | AGU3: 2 | AGV3: 1 | AGW3: 1 | AGX3: 1 | AGY3: 2 | AGZ3: 3 | AHA3: 0 | AHB3: 2 | AHC3: 2 | AHD3: 0 | AHE3: 1 | AHF3: 1 | AHG3: 2 | AHH3: 3 | AHI3: 4 | AHJ3: 0 | AHK3: 0 | AHL3: 1 | AHM3: 0 | AHN3: 1 | AHO3: 2 | AHP3: 0 | AHQ3: 0 | AHR3: 2 | AHS3: 1 | AHT3: 0 | AHU3: 0 | AHV3: 0 | AHW3: 1 | AHX3: 0 | AHY3: 0 | AHZ3: 1 | AIA3: 0 | AIB3: 1 | AIC3: 0 | AID3: 1 | AIE3: 0 | AIF3: 0 | AIG3: 0 | AIH3: 1 | AII3: 0 | AIJ3: 1 | AIK3: 0 | AIL3: 0 | AIM3: 0 | AIN3: 0 | AIO3: 0 | AIP3: 0 | AIQ3: 0 | AIR3: 1 | AIS3: 1 | AIT3: 0 | AIU3: 0 | AIV3: 0 | AIW3: 1 | AIX3: 1 | AIY3: 0 | AIZ3: 1 | AJA3: 0 | AJB3: 0 | AJC3: 0 | AJD3: 0 | AJE3: 0 | AJF3: 0 | AJG3: 0 | AJH3: 0 | AJI3: 0 | AJJ3: 1 | AJK3: 0 | AJL3: 1 | AJM3: 0 | AJN3: 0 | AJO3: 0 | AJP3: 0 | AJQ3: 0 | AJR3: 1 | AJS3: 0 | AJT3: 0 | AJU3: 0 | AJV3: 0 | AJW3: 0 | AJX3: 0 | AJY3: 0 | AJZ3: 0 | AKA3: 0 | AKB3: 0 | AKC3: 0 | AKD3: 0 | AKE3: 1 | AKF3: 0 | AKG3: 1 | AKH3: 2 | AKI3: 0 | AKJ3: 0 | AKK3: 1 | AKL3: 1 | AKM3: 0 | AKN3: 1 | AKO3: 1 | AKP3: 0 | AKQ3: 0 | AKR3: 0 | AKS3: 0 | AKT3: 0 | AKU3: 0 | AKV3: 0 | AKW3: 0 | AKX3: 0 | AKY3: 1 | AKZ3: 1 | ALA3: 1 | ALB3: 3 | ALC3: 1 | ALD3: 0 | ALE3: 0 | ALF3: 1 | ALG3: 2 | ALH3: 0 | ALI3: 1 | ALJ3: 3 | ALK3: 0 | ALL3: 1 | ALM3: 0 | ALN3: 0 | ALO3: 0 | ALP3: 0 | ALQ3: 0 | ALR3: 0 | ALS3: 2 | ALT3: 1 | ALU3: 1 | ALV3: 0 | ALW3: 0 | ALX3: 2 | ALY3: 1 | ALZ3: 0 | AMA3: 1 | AMB3: 1 | AMC3: 1 | AMD3: 0 | AME3: 1 | AMF3: 0 | AMG3: 0 | AMH3: 1 | AMI3: 2 | AMJ3: 2 | AMK3: 0 | AML3: 0 | AMM3: 1 | AMN3: 3 | AMO3: 0 | AMP3: 4 | AMQ3: 0 | AMR3: 1 | AMS3: 3 | AMT3: 0 | AMU3: 0 | AMV3: 0 | AMW3: 0 | AMX3: 1 | AMY3: 4 | AMZ3: 1 | ANA3: 0 | ANB3: 0 | ANC3: 1 | AND3: 0 | ANE3: 0 | ANF3: 1 | ANG3: 0 | ANH3: 1 | ANI3: 2 | ANJ3: 0 | ANK3: 0 | ANL3: 0 | ANM3: 1 | ANN3: 1 | ANO3: 0 | ANP3: 1 | ANQ3: 0 | ANR3: 0 | ANS3: 0 | ANT3: 0 | ANU3: 0 | ANV3: 0 | ANW3: 0 | ANX3: 1 | ANY3: 0 | ANZ3: 1 | AOA3: 0 | AOB3: 1 | AOC3: 0 | AOD3: 1 | AOE3: 0 | AOF3: 1 | AOG3: 1 | AOH3: 1 | AOI3: 0 | AOJ3: 2 | AOK3: 0 | AOL3: 2 | AOM3: 0 | AON3: 0 | AOO3: 0 | AOP3: 0 | AOQ3: 0 | AOR3: 1 | AOS3: 0 | AOT3: 0 | AOU3: 0 | AOV3: 1 | AOW3: 0 | AOX3: 1 | AOY3: 1 | AOZ3: 0 | APA3: 1 | APB3: 1 | APC3: 0 | APD3: 0 | APE3: 0 | APF3: 0 | APG3: 0 | APH3: 1 | API3: 0 | APJ3: 1 | APK3: 0 | APL3: 1 | APM3: 1 | APN3: 1 | APO3: 0 | APP3: 0 | APQ3: 1 | APR3: 1 | APS3: 0 | APT3: 0 | APU3: 0 | APV3: 0 | APW3: 0 | APX3: 0 | APY3: 0 | APZ3: 0 | AQA3: 0 | AQB3: 1 | AQC3: 1 | AQD3: 0 | AQE3: 0 | AQF3: 0 | AQG3: 0 | AQH3: 2 | AQI3: 1 | AQJ3: 0 | AQK3: 1 | AQL3: 0 | AQM3: 0 | AQN3: 0 | AQO3: 0 | AQP3: 0 | AQQ3: 0 | AQR3: 1 | AQS3: 0 | AQT3: 0 | AQU3: 1 | AQV3: 0 | AQW3: 1 | AQX3: 0 | AQY3: 1 | AQZ3: 1 | ARA3: 1 | ARB3: 0 | ARC3: 0 | ARD3: 0 | ARE3: 0 | ARF3: 1 | ARG3: 0 | ARH3: 0 | ARI3: 1 | ARJ3: 0 | ARK3: 0 | ARL3: 0 | ARM3: 0 | ARN3: 0 | ARO3: 0 | ARP3: 0 | ARQ3: 0 | ARR3: 0 | ARS3: 0 | ART3: 0 | ARU3: 2 | ARV3: 0 | ARW3: 0 | ARX3: 0 | ARY3: 0 | ARZ3: 0 | ASA3: 1 | ASB3: 0 | ASC3: 0 | ASD3: 0 | ASE3: 0 | ASF3: 0 | ASG3: 0 | ASH3: 1 | ASI3: 0 | ASJ3: 0 | ASK3: 0 | ASL3: 0 | ASM3: 0 | ASN3: 0 | ASO3: 0 | ASP3: 0 | ASQ3: 0 | ASR3: 0 | ASS3: 0 | AST3: 0 | ASU3: 0 | ASV3: 0 | ASW3: 0 | ASX3: 0 | ASY3: 0 | ASZ3: 1 | ATA3: 0
A4: 03 | B4: 804708 | C4: BAJA CALIFORNIA SUR | D4: 0 | E4: 0 | F4: 0 | G4: 0 | H4: 0 | I4: 0 | J4: 0 | K4: 0 | L4: 0 | M4: 0 | N4: 0 | O4: 0 | P4: 1 | Q4: 0 | R4: 1 | S4: 0 | T4: 0 | U4: 0 | V4: 1 | W4: 2 | X4: 0 | Y4: 0 | Z4: 1 | AA4: 0 | AB4: 0 | AC4: 1 | AD4: 1 | AE4: 2 | AF4: 0 | AG4: 0 | AH4: 1 | AI4: 1 | AJ4: 1 | AK4: 0 | AL4: 1 | AM4: 1 | AN4: 2 | AO4: 0 | AP4: 1 | AQ4: 1 | AR4: 2 | AS4: 0 | AT4: 1 | AU4: 1 | AV4: 0 | AW4: 0 | AX4: 0 | AY4: 1 | AZ4: 1 | BA4: 0 | BB4: 2 | BC4: 0 | BD4: 2 | BE4: 0 | BF4: 1 | BG4: 1 | BH4: 0 | BI4: 1 | BJ4: 1 | BK4: 0 | BL4: 1 | BM4: 1 | BN4: 1 | BO4: 0 | BP4: 1 | BQ4: 0 | BR4: 1 | BS4: 0 | BT4: 1 | BU4: 0 | BV4: 1 | BW4: 2 | BX4: 0 | BY4: 1 | BZ4: 0 | CA4: 0 | CB4: 1 | CC4: 1 | CD4: 2 | CE4: 3 | CF4: 3 | CG4: 0 | CH4: 0 | CI4: 0 | CJ4: 1 | CK4: 0 | CL4: 2 | CM4: 2 | CN4: 2 | CO4: 4 | CP4: 4 | CQ4: 1 | CR4: 1 | CS4: 1 | CT4: 1 | CU4: 2 | CV4: 0 | CW4: 1 | CX4: 1 | CY4: 1 | CZ4: 1 | DA4: 1 | DB4: 3 | DC4: 0 | DD4: 1 | DE4: 5 | DF4: 1 | DG4: 5 | DH4: 4 | DI4: 1 | DJ4: 2 | DK4: 2 | DL4: 0 | DM4: 2 | DN4: 3 | DO4: 3 | DP4: 5 | DQ4: 7 | DR4: 6 | DS4: 4 | DT4: 6 | DU4: 2 | DV4: 8 | DW4: 2 | DX4: 3 | DY4: 8 | DZ4: 4 | EA4: 5 | EB4: 5 | EC4: 7 | ED4: 5 | EE4: 10 | EF4: 6 | EG4: 8 | EH4: 9 | EI4: 13 | EJ4: 4 | EK4: 8 | EL4: 6 | EM4: 6 | EN4: 5 | EO4: 8 | EP4: 3 | EQ4: 7 | ER4: 9 | ES4: 8 | ET4: 5 | EU4: 13 | EV4: 7 | EW4: 6 | EX4: 9 | EY4: 7 | EZ4: 9 | FA4: 10 | FB4: 12 | FC4: 9 | FD4: 8 | FE4: 8 | FF4: 4 | FG4: 7 | FH4: 8 | FI4: 10 | FJ4: 4 | FK4: 4 | FL4: 5 | FM4: 8 | FN4: 4 | FO4: 10 | FP4: 6 | FQ4: 11 | FR4: 7 | FS4: 3 | FT4: 4 | FU4: 3 | FV4: 1 | FW4: 9 | FX4: 9 | FY4: 4 | FZ4: 1 | GA4: 3 | GB4: 5 | GC4: 3 | GD4: 3 | GE4: 1 | GF4: 10 | GG4: 3 | GH4: 5 | GI4: 3 | GJ4: 3 | GK4: 3 | GL4: 4 | GM4: 2 | GN4: 3 | GO4: 2 | GP4: 4 | GQ4: 4 | GR4: 5 | GS4: 2 | GT4: 2 | GU4: 0 | GV4: 3 | GW4: 5 | GX4: 4 | GY4: 2 | GZ4: 4 | HA4: 4 | HB4: 2 | HC4: 2 | HD4: 0 | HE4: 2 | HF4: 1 | HG4: 4 | HH4: 1 | HI4: 3 | HJ4: 3 | HK4: 2 | HL4: 4 | HM4: 0 | HN4: 6 | HO4: 1 | HP4: 4 | HQ4: 2 | HR4: 2 | HS4: 4 | HT4: 2 | HU4: 0 | HV4: 2 | HW4: 3 | HX4: 4 | HY4: 2 | HZ4: 3 | IA4: 3 | IB4: 3 | IC4: 2 | ID4: 1 | IE4: 2 | IF4: 2 | IG4: 1 | IH4: 6 | II4: 4 | IJ4: 1 | IK4: 4 | IL4: 1 | IM4: 3 | IN4: 3 | IO4: 1 | IP4: 1 | IQ4: 2 | IR4: 2 | IS4: 1 | IT4: 5 | IU4: 1 | IV4: 3 | IW4: 4 | IX4: 1 | IY4: 0 | IZ4: 3 | JA4: 0 | JB4: 5 | JC4: 4 | JD4: 0 | JE4: 3 | JF4: 5 | JG4: 2 | JH4: 3 | JI4: 3 | JJ4: 0 | JK4: 2 | JL4: 3 | JM4: 2 | JN4: 2 | JO4: 7 | JP4: 1 | JQ4: 2 | JR4: 2 | JS4: 1 | JT4: 2 | JU4: 6 | JV4: 1 | JW4: 8 | JX4: 3 | JY4: 3 | JZ4: 5 | KA4: 3 | KB4: 9 | KC4: 5 | KD4: 4 | KE4: 3 | KF4: 6 | KG4: 3 | KH4: 3 | KI4: 1 | KJ4: 10 | KK4: 7 | KL4: 5 | KM4: 8 | KN4: 11 | KO4: 5 | KP4: 4 | KQ4: 6 | KR4: 8 | KS4: 9 | KT4: 4 | KU4: 7 | KV4: 12 | KW4: 10 | KX4: 5 | KY4: 6 | KZ4: 13 | LA4: 11 | LB4: 7 | LC4: 16 | LD4: 5 | LE4: 10 | LF4: 7 | LG4: 10 | LH4: 4 | LI4: 6 | LJ4: 14 | LK4: 5 | LL4: 6 | LM4: 13 | LN4: 8 | LO4: 16 | LP4: 10 | LQ4: 9 | LR4: 11 | LS4: 6 | LT4: 7 | LU4: 10 | LV4: 5 | LW4: 5 | LX4: 7 | LY4: 6 | LZ4: 7 | MA4: 4 | MB4: 6 | MC4: 5 | MD4: 5 | ME4: 8 | MF4: 6 | MG4: 6 | MH4: 4 | MI4: 9 | MJ4: 2 | MK4: 4 | ML4: 3 | MM4: 3 | MN4: 3 | MO4: 8 | MP4: 4 | MQ4: 2 | MR4: 0 | MS4: 0 | MT4: 2 | MU4: 2 | MV4: 1 | MW4: 5 | MX4: 3 | MY4: 1 | MZ4: 3 | NA4: 0 | NB4: 3 | NC4: 3 | ND4: 4 | NE4: 5 | NF4: 2 | NG4: 2 | NH4: 1 | NI4: 0 | NJ4: 5 | NK4: 0 | NL4: 3 | NM4: 3 | NN4: 2 | NO4: 1 | NP4: 1 | NQ4: 2 | NR4: 2 | NS4: 0 | NT4: 0 | NU4: 2 | NV4: 4 | NW4: 1 | NX4: 6 | NY4: 4 | NZ4: 0 | OA4: 0 | OB4: 3 | OC4: 0 | OD4: 2 | OE4: 1 | OF4: 3 | OG4: 1 | OH4: 3 | OI4: 5 | OJ4: 6 | OK4: 0 | OL4: 1 | OM4: 0 | ON4: 3 | OO4: 3 | OP4: 3 | OQ4: 2 | OR4: 1 | OS4: 0 | OT4: 5 | OU4: 1 | OV4: 2 | OW4: 3 | OX4: 0 | OY4: 3 | OZ4: 2 | PA4: 2 | PB4: 0 | PC4: 3 | PD4: 0 | PE4: 1 | PF4: 0 | PG4: 3 | PH4: 3 | PI4: 3 | PJ4: 2 | PK4: 2 | PL4: 1 | PM4: 3 | PN4: 3 | PO4: 6 | PP4: 3 | PQ4: 2 | PR4: 1 | PS4: 4 | PT4: 7 | PU4: 0 | PV4: 2 | PW4: 3 | PX4: 2 | PY4: 1 | PZ4: 2 | QA4: 1 | QB4: 0 | QC4: 4 | QD4: 1 | QE4: 4 | QF4: 1 | QG4: 2 | QH4: 2 | QI4: 0 | QJ4: 0 | QK4: 4 | QL4: 2 | QM4: 6 | QN4: 4 | QO4: 2 | QP4: 6 | QQ4: 2 | QR4: 6 | QS4: 6 | QT4: 6 | QU4: 4 | QV4: 6 | QW4: 14 | QX4: 4 | QY4: 6 | QZ4: 8 | RA4: 11 | RB4: 10 | RC4: 15 | RD4: 12 | RE4: 17 | RF4: 13 | RG4: 14 | RH4: 18 | RI4: 14 | RJ4: 12 | RK4: 19 | RL4: 21 | RM4: 13 | RN4: 17 | RO4: 12 | RP4: 12 | RQ4: 17 | RR4: 12 | RS4: 17 | RT4: 10 | RU4: 14 | RV4: 15 | RW4: 12 | RX4: 13 | RY4: 15 | RZ4: 15 | SA4: 20 | SB4: 11 | SC4: 21 | SD4: 10 | SE4: 5 | SF4: 13 | SG4: 18 | SH4: 13 | SI4: 10 | SJ4: 8 | SK4: 10 | SL4: 7 | SM4: 12 | SN4: 7 | SO4: 2 | SP4: 11 | SQ4: 15 | SR4: 7 | SS4: 7 | ST4: 11 | SU4: 12 | SV4: 9 | SW4: 8 | SX4: 6 | SY4: 9 | SZ4: 4 | TA4: 9 | TB4: 5 | TC4: 6 | TD4: 3 | TE4: 4 | TF4: 4 | TG4: 5 | TH4: 7 | TI4: 6 | TJ4: 8 | TK4: 6 | TL4: 5 | TM4: 6 | TN4: 1 | TO4: 4 | TP4: 4 | TQ4: 4 | TR4: 6 | TS4: 4 | TT4: 1 | TU4: 3 | TV4: 5 | TW4: 3 | TX4: 2 | TY4: 5 | TZ4: 4 | UA4: 2 | UB4: 2 | UC4: 7 | UD4: 1 | UE4: 2 | UF4: 0 | UG4: 3 | UH4: 2 | UI4: 4 | UJ4: 2 | UK4: 3 | UL4: 2 | UM4: 2 | UN4: 2 | UO4: 1 | UP4: 1 | UQ4: 2 | UR4: 1 | US4: 0 | UT4: 1 | UU4: 0 | UV4: 4 | UW4: 4 | UX4: 3 | UY4: 1 | UZ4: 1 | VA4: 2 | VB4: 2 | VC4: 3 | VD4: 7 | VE4: 1 | VF4: 4 | VG4: 0 | VH4: 2 | VI4: 0 | VJ4: 0 | VK4: 1 | VL4: 0 | VM4: 1 | VN4: 0 | VO4: 1 | VP4: 1 | VQ4: 2 | VR4: 0 | VS4: 1 | VT4: 0 | VU4: 0 | VV4: 1 | VW4: 0 | VX4: 1 | VY4: 0 | VZ4: 0 | WA4: 1 | WB4: 0 | WC4: 0 | WD4: 0 | WE4: 2 | WF4: 0 | WG4: 0 | WH4: 0 | WI4: 1 | WJ4: 0 | WK4: 0 | WL4: 2 | WM4: 0 | WN4: 2 | WO4: 2 | WP4: 1 | WQ4: 1 | WR4: 2 | WS4: 0 | WT4: 0 | WU4: 0 | WV4: 0 | WW4: 2 | WX4: 1 | WY4: 0 | WZ4: 1 | XA4: 5 | XB4: 0 | XC4: 2 | XD4: 0 | XE4: 1 | XF4: 0 | XG4: 1 | XH4: 0 | XI4: 1 | XJ4: 0 | XK4: 1 | XL4: 1 | XM4: 0 | XN4: 3 | XO4: 0 | XP4: 0 | XQ4: 0 | XR4: 0 | XS4: 0 | XT4: 2 | XU4: 0 | XV4: 0 | XW4: 0 | XX4: 1 | XY4: 0 | XZ4: 1 | YA4: 1 | YB4: 2 | YC4: 0 | YD4: 0 | YE4: 1 | YF4: 0 | YG4: 1 | YH4: 0 | YI4: 2 | YJ4: 2 | YK4: 4 | YL4: 5 | YM4: 0 | YN4: 3 | YO4: 1 | YP4: 0 | YQ4: 2 | YR4: 1 | YS4: 4 | YT4: 9 | YU4: 9 | YV4: 6 | YW4: 4 | YX4: 4 | YY4: 6 | YZ4: 8 | ZA4: 2 | ZB4: 9 | ZC4: 5 | ZD4: 2 | ZE4: 9 | ZF4: 6 | ZG4: 5 | ZH4: 4 | ZI4: 6 | ZJ4: 8 | ZK4: 1 | ZL4: 4 | ZM4: 3 | ZN4: 5 | ZO4: 2 | ZP4: 2 | ZQ4: 6 | ZR4: 4 | ZS4: 4 | ZT4: 0 | ZU4: 8 | ZV4: 8 | ZW4: 6 | ZX4: 1 | ZY4: 2 | ZZ4: 2 | AAA4: 4 | AAB4: 4 | AAC4: 4 | AAD4: 1 | AAE4: 3 | AAF4: 4 | AAG4: 2 | AAH4: 5 | AAI4: 2 | AAJ4: 3 | AAK4: 1 | AAL4: 2 | AAM4: 1 | AAN4: 0 | AAO4: 2 | AAP4: 2 | AAQ4: 0 | AAR4: 4 | AAS4: 1 | AAT4: 1 | AAU4: 0 | AAV4: 1 | AAW4: 0 | AAX4: 0 | AAY4: 1 | AAZ4: 1 | ABA4: 0 | ABB4: 2 | ABC4: 1 | ABD4: 0 | ABE4: 1 | ABF4: 1 | ABG4: 0 | ABH4: 1 | ABI4: 0 | ABJ4: 0 | ABK4: 1 | ABL4: 1 | ABM4: 1 | ABN4: 0 | ABO4: 0 | ABP4: 0 | ABQ4: 1 | ABR4: 0 | ABS4: 1 | ABT4: 0 | ABU4: 0 | ABV4: 0 | ABW4: 1 | ABX4: 0 | ABY4: 0 | ABZ4: 1 | ACA4: 0 | ACB4: 0 | ACC4: 0 | ACD4: 0 | ACE4: 0 | ACF4: 0 | ACG4: 0 | ACH4: 0 | ACI4: 0 | ACJ4: 0 | ACK4: 0 | ACL4: 0 | ACM4: 0 | ACN4: 0 | ACO4: 0 | ACP4: 0 | ACQ4: 0 | ACR4: 0 | ACS4: 0 | ACT4: 0 | ACU4: 0 | ACV4: 1 | ACW4: 0 | ACX4: 0 | ACY4: 0 | ACZ4: 0 | ADA4: 0 | ADB4: 0 | ADC4: 1 | ADD4: 0 | ADE4: 0 | ADF4: 0 | ADG4: 0 | ADH4: 0 | ADI4: 0 | ADJ4: 0 | ADK4: 0 | ADL4: 0 | ADM4: 0 | ADN4: 0 | ADO4: 0 | ADP4: 0 | ADQ4: 0 | ADR4: 1 | ADS4: 0 | ADT4: 0 | ADU4: 1 | ADV4: 0 | ADW4: 0 | ADX4: 0 | ADY4: 1 | ADZ4: 0 | AEA4: 0 | AEB4: 0 | AEC4: 0 | AED4: 0 | AEE4: 0 | AEF4: 0 | AEG4: 0 | AEH4: 0 | AEI4: 0 | AEJ4: 0 | AEK4: 1 | AEL4: 0 | AEM4: 0 | AEN4: 1 | AEO4: 0 | AEP4: 1 | AEQ4: 3 | AER4: 0 | AES4: 0 | AET4: 0 | AEU4: 0 | AEV4: 0 | AEW4: 1 | AEX4: 0 | AEY4: 1 | AEZ4: 0 | AFA4: 1 | AFB4: 0 | AFC4: 1 | AFD4: 1 | AFE4: 0 | AFF4: 2 | AFG4: 2 | AFH4: 1 | AFI4: 0 | AFJ4: 0 | AFK4: 0 | AFL4: 3 | AFM4: 0 | AFN4: 0 | AFO4: 2 | AFP4: 2 | AFQ4: 0 | AFR4: 1 | AFS4: 1 | AFT4: 2 | AFU4: 2 | AFV4: 0 | AFW4: 2 | AFX4: 0 | AFY4: 1 | AFZ4: 1 | AGA4: 1 | AGB4: 0 | AGC4: 0 | AGD4: 1 | AGE4: 1 | AGF4: 2 | AGG4: 0 | AGH4: 1 | AGI4: 3 | AGJ4: 1 | AGK4: 1 | AGL4: 2 | AGM4: 1 | AGN4: 1 | AGO4: 1 | AGP4: 0 | AGQ4: 1 | AGR4: 1 | AGS4: 0 | AGT4: 0 | AGU4: 2 | AGV4: 2 | AGW4: 0 | AGX4: 0 | AGY4: 0 | AGZ4: 0 | AHA4: 0 | AHB4: 1 | AHC4: 2 | AHD4: 1 | AHE4: 0 | AHF4: 0 | AHG4: 1 | AHH4: 0 | AHI4: 1 | AHJ4: 0 | AHK4: 1 | AHL4: 1 | AHM4: 0 | AHN4: 1 | AHO4: 0 | AHP4: 0 | AHQ4: 1 | AHR4: 2 | AHS4: 0 | AHT4: 0 | AHU4: 0 | AHV4: 0 | AHW4: 0 | AHX4: 0 | AHY4: 0 | AHZ4: 0 | AIA4: 0 | AIB4: 0 | AIC4: 0 | AID4: 0 | AIE4: 0 | AIF4: 0 | AIG4: 0 | AIH4: 0 | AII4: 0 | AIJ4: 0 | AIK4: 0 | AIL4: 0 | AIM4: 3 | AIN4: 0 | AIO4: 0 | AIP4: 0 | AIQ4: 0 | AIR4: 1 | AIS4: 0 | AIT4: 0 | AIU4: 0 | AIV4: 0 | AIW4: 0 | AIX4: 0 | AIY4: 0 | AIZ4: 0 | AJA4: 0 | AJB4: 0 | AJC4: 0 | AJD4: 0 | AJE4: 0 | AJF4: 0 | AJG4: 0 | AJH4: 0 | AJI4: 0 | AJJ4: 0 | AJK4: 0 | AJL4: 0 | AJM4: 0 | AJN4: 0 | AJO4: 0 | AJP4: 0 | AJQ4: 0 | AJR4: 0 | AJS4: 1 | AJT4: 0 | AJU4: 0 | AJV4: 0 | AJW4: 0 | AJX4: 0 | AJY4: 0 | AJZ4: 0 | AKA4: 0 | AKB4: 0 | AKC4: 0 | AKD4: 0 | AKE4: 0 | AKF4: 0 | AKG4: 0 | AKH4: 0 | AKI4: 0 | AKJ4: 0 | AKK4: 0 | AKL4: 0 | AKM4: 0 | AKN4: 0 | AKO4: 0 | AKP4: 0 | AKQ4: 0 | AKR4: 0 | AKS4: 0 | AKT4: 0 | AKU4: 0 | AKV4: 0 | AKW4: 0 | AKX4: 0 | AKY4: 0 | AKZ4: 1 | ALA4: 0 | ALB4: 0 | ALC4: 0 | ALD4: 0 | ALE4: 0 | ALF4: 0 | ALG4: 0 | ALH4: 0 | ALI4: 0 | ALJ4: 0 | ALK4: 0 | ALL4: 0 | ALM4: 0 | ALN4: 1 | ALO4: 0 | ALP4: 0 | ALQ4: 0 | ALR4: 0 | ALS4: 0 | ALT4: 0 | ALU4: 0 | ALV4: 0 | ALW4: 0 | ALX4: 0 | ALY4: 1 | ALZ4: 0 | AMA4: 0 | AMB4: 0 | AMC4: 0 | AMD4: 0 | AME4: 0 | AMF4: 0 | AMG4: 0 | AMH4: 0 | AMI4: 0 | AMJ4: 0 | AMK4: 0 | AML4: 0 | AMM4: 0 | AMN4: 0 | AMO4: 1 | AMP4: 0 | AMQ4: 1 | AMR4: 0 | AMS4: 0 | AMT4: 0 | AMU4: 0 | AMV4: 0 | AMW4: 0 | AMX4: 0 | AMY4: 0 | AMZ4: 0 | ANA4: 0 | ANB4: 0 | ANC4: 0 | AND4: 0 | ANE4: 1 | ANF4: 0 | ANG4: 0 | ANH4: 0 | ANI4: 0 | ANJ4: 0 | ANK4: 0 | ANL4: 1 | ANM4: 0 | ANN4: 2 | ANO4: 0 | ANP4: 0 | ANQ4: 0 | ANR4: 1 | ANS4: 0 | ANT4: 0 | ANU4: 0 | ANV4: 0 | ANW4: 1 | ANX4: 0 | ANY4: 0 | ANZ4: 0 | AOA4: 0 | AOB4: 0 | AOC4: 0 | AOD4: 0 | AOE4: 1 | AOF4: 0 | AOG4: 0 | AOH4: 0 | AOI4: 0 | AOJ4: 0 | AOK4: 0 | AOL4: 0 | AOM4: 0 | AON4: 0 | AOO4: 0 | AOP4: 0 | AOQ4: 0 | AOR4: 0 | AOS4: 0 | AOT4: 0 | AOU4: 0 | AOV4: 0 | AOW4: 1 | AOX4: 0 | AOY4: 0 | AOZ4: 0 | APA4: 0 | APB4: 0 | APC4: 1 | APD4: 0 | APE4: 0 | APF4: 0 | APG4: 0 | APH4: 1 | API4: 1 | APJ4: 0 | APK4: 0 | APL4: 0 | APM4: 0 | APN4: 0 | APO4: 0 | APP4: 2 | APQ4: 0 | APR4: 1 | APS4: 0 | APT4: 0 | APU4: 0 | APV4: 0 | APW4: 0 | APX4: 0 | APY4: 0 | APZ4: 1 | AQA4: 1 | AQB4: 1 | AQC4: 0 | AQD4: 0 | AQE4: 0 | AQF4: 0 | AQG4: 0 | AQH4: 0 | AQI4: 0 | AQJ4: 0 | AQK4: 0 | AQL4: 0 | AQM4: 1 | AQN4: 1 | AQO4: 0 | AQP4: 0 | AQQ4: 1 | AQR4: 0 | AQS4: 0 | AQT4: 0 | AQU4: 0 | AQV4: 0 | AQW4: 0 | AQX4: 0 | AQY4: 0 | AQZ4: 0 | ARA4: 0 | ARB4: 0 | ARC4: 0 | ARD4: 0 | ARE4: 0 | ARF4: 0 | ARG4: 0 | ARH4: 0 | ARI4: 0 | ARJ4: 0 | ARK4: 0 | ARL4: 0 | ARM4: 0 | ARN4: 0 | ARO4: 0 | ARP4: 0 | ARQ4: 0 | ARR4: 0 | ARS4: 0 | ART4: 0 | ARU4: 0 | ARV4: 0 | ARW4: 0 | ARX4: 0 | ARY4: 0 | ARZ4: 0 | ASA4: 0 | ASB4: 0 | ASC4: 0 | ASD4: 0 | ASE4: 0 | ASF4: 0 | ASG4: 0 | ASH4: 0 | ASI4: 0 | ASJ4: 0 | ASK4: 0 | ASL4: 0 | ASM4: 0 | ASN4: 0 | ASO4: 0 | ASP4: 0 | ASQ4: 0 | ASR4: 0 | ASS4: 0 | AST4: 0 | ASU4: 0 | ASV4: 0 | ASW4: 0 | ASX4: 0 | ASY4: 0 | ASZ4: 0 | ATA4: 0
